Workbook

Sheet Наряд на РПО
E1: Проект АЭС «Эль-Дабаа» | H1: Наряд-допуск на производство работ повышенной опасности Permit to work for the execution of highly hazardous work
I4: Наряд-допуск №: Permit to work №:
A6: Наименование организации: Company Name: | G6: Филиал Общества с ограниченной ответственностью «Трест Росспецэнергомонтаж» Египет, г. Каир Branch office of "Trest RosSEM" LLC, Cairo, Egypt
A8: Дата выдачи: Issue date: | E8: =TODAY() -> 46316 | I8: Время выдачи: Issue time: | N8: 0.29166667 | S8: Количество дней действия Valid in days | Y8: 15
A10: Действителен до: Valid until: | E10: =E8+14 -> 46330 | I10: Время завершения: Completion time: | N10: 0.70833333
A12: 1 | B12: Руководитель работ (Ф.И.О.): Head of works (full name): | I12: Pavlov V.E. | P12: (подпись / signature) | S12: Должность: Position: | V12: Foreman
A14: 2 | B14: Ответственный исполнитель работ (Ф.И.О.): Responsible work executor (full name): | P14: (подпись / signature) | S14: Должность: Position:
A16: 3 | B16: Наряд-допуск согласован: The prmit to work has been approved: | J16: Специалист по ОТ HSE | N16: (Ф.И.О. / full name) | S16: (подпись / signature) | V16: Дата: Date: | X16: =E8 -> 46316
A18: 4 | B18: Описание работ: Description of the work: | H18: Ремонт дефектов поверхностей ЖК, бетонной смесью или ремонтным составом/Repair of LCD surface defects with concrete mixture or repair compound
B20: Место проведения работ: Place of work: | H20: 10UJA from elev. -0.100/ +6.800
A22: 5 | B22: Работы производятся в соответствии с: The work is carried out in accordance with: | K22: Технологический регламент ED.A.A&&&.&.&&&&&&.&&&&&&.012.KB.0001.R Ревизия С-02
K24: (указывается номер ОС ППР, ППР, ТК и т.д.) (the number of HC WEP, WEP, MS, etc. is indicated)
A26: 6 | B26: Приложения: Attachments:
B28: Процедуры Procedures | G28: Журнал анализа воздушной среды Log Book of Air Environment Analysis | L28: Инспекции площадки Site inspections | Q28: Акт выполнения выемки грунта Excavation certificate | V28: Акт оператора Operators certificate
B32: Оценка рисков Risk assessment | G32: План производства работ на высоте WEP for works at height | L32: Схемы / План Schematics / Plan | Q32: График производства совмещенных работ Access route cleared | V32: Запрос NPPA NPPA Request
B35: Акт электроизоляции (EIC.) Electrical Isolation Certificate (EIC.) | G35: Акт механической изоляции (MIC.) Mechanical Isolation Certificate (MIC.) | L35: Акты на грузоподъемные устройства Lifting tools certificates | Q35: Вход в замкнутое/ ограниченное пространство (Наряд № _______ ) Vessel/Confined Space Entry (PTW № _____ ) | V35: Связанный наряд на выполнение работ (Наряд № ___________ ) Linked work Permit (PTW № ___________ )
A41: 7 | B41: Вредные и опасные производственные факторы: Harmful and hazardous production factors:
B43: Воспламеняющиеся вещества Flammables substances | G43: Сосуды под давлением Preasure vessels | L43: Опасность над головой Hazard is overhead | Q43: Недостаточная освещенность Insufficient illumination | V43: Иное: Other:
B46: Нагретые поверхности, при соприкосновении с которыми можно получить ожог Heated surfaces that can lead to burns when contacting | G46: Подвижные части оборудования Moving parts of prodaction equipment | L46: Работа в ограниченном и замкнутом пространстве Working ia a enclosed and confined space | Q46: Воздействие шума Noise exposure | V46: Иное: Other:
B52: Взрывоопасные вещества Explosive substances | G52: Движущиеся машины и механизмы Moving machines and mechanisms | L52: Пар Steam | Q52: Работа на высоте Working at height | V52: Иное: Other:
B56: Недостаток кислорода Lack of oxygen | G56: Опасные химические вещества и жидкости Dangerous chemicals and liqids | L56: Дым / пыль Smoke / dust | Q56: Высокое/низкое давление High / Low pressure | V56: Иное: Other:
B61: Опасность поражения электрическим током Dangerous of electric shock | G61: Вибрация Vibrations | L61: Острые кромки, углы, торчащие штыри Sharp edges, corners, protruding pins | Q61: Высокая/низкая температура High / low temperature | V61: Иное: Other:
A66: 8 | B66: Оборудование и инструмент: Equipment and tools:
B68: Гидравлический подъемник/мобильная подъемная рабочая платформа Hydraulic lift/mobile lifting work platform | G68: Сварочное оборудование Welding equipment | L68: Световая мачта Light mast | Q68: Кран Crane | V68: Дорожный каток Road roller
B73: Строительные леса Scaffolding | G73: Уборочный инвентарь Cleaning equipment | L73: Прожектор Floodlight | Q73: Погрузчик Loader | V73: Виброплита Vibrating plate
B75: Лестницы Ladders | G75: Бетононасос Concrete pump | L75: Бензоинструмент Gasoline-powered tools | Q75: Грейдер Grader | V75: Иное: Other:
B77: Станочное оборудование Machine tools | G77: Глубинный вибратор/ виброрейка Deep vibrator/ vibration rack | L77: Тепловая пушка Heat gun | Q77: Бульдозер Bulldozer | V77: Иное: Other:
B81: Ручной электрический инструмент Hand-held electric tool | G81: Инструмент для работы с бетоном Tool for concrete works | L81: Горелка Burner | Q81: Экскаватор Excavator | V81: Иное: Other:
B85: Ручной инструмент Hand tool | G85: Воздушный компрессор Air compressor | L85: Баллон со сжатым газом Compressed gas cylinder | Q85: Самосвал Dump truck | V85: Иное: Other:
A88: 9 | B88: СИЗ, меры безопасности: PPE, safety measures:
B90: СИЗ (5М) PPE (5M) | G90: Химически стойкие перчатки/перчатки покрытые ПВХ Chemically resistant gloves/PVC coated gloves | L90: Проверка лестницы Ladder check | Q90: Блокировка и маркировка Interlocking and labeling | V90: Связь Communication
B95: Страховочная привязь Safety harness | G95: Одноразовый комбинезон Disposable coveralls | L95: Сброс давления Pressure relief | Q95: Знаки безопасности Safty signs | V95: Измерения воздушной среды Measurements of the air environment
B98: Анкерная линия Г/В Anchor line G/V | G98: Искробезопасный/особый инструмент Intrisically safe/special tool | L98: Газоотвод Vent | Q98: Ограждение Fence | V98: Перекрытие дорог Road closures
B101: Пылезащитная маска/противогаз Dust mask/Gas mask | G101: Защита от искр Protection against sparks | L101: Достаточная вентиляция Adequate ventilation | Q101: Предохранительные сетки Safety nets | V101: Акты технического осмотра Technical inspection certificates
B104: Лицевой щиток Face shield | G104: Огнетушители Fire extinguishers | L104: Достаточное освещение Sufficient lighting | Q104: Безопасный доступ/вход Secure access/entrance | V104: Наблюдающий Supervisor
B107: Беруши/наушники Earplugs/headphones | G107: Аптечка первой медицинской помощи First aid kit | L107: Страхующий Helper | Q107: Аварийный доступ/выход Emergency access/exit | V107: Иное: Other:
B110: Антивибрационные перчатки Anti-vibration gloves | G110: Проверка лесов Scaffolding check | L110: Определение подземных коммуникаций Underground utilities detection | Q110: Проверка рабочего места Workplace check | V110: Иное: Other:
A114: Системы обеспечения безопасности работ на высоте: Safety systems for work at height: | L114: Состав системы: Composition of the system:
A116: FALSE | B116: Удерживающие системы Retention systems | L116: =IF(A116,"удерживающая привязь, соединительный элемент (карабин), анкерная точка крепления, строп регулируемой длины retaining harness, connecting element (carabiner), anchor point, adjustable length lanyard","-") -> -
A119: FALSE | B119: Системы позиционирования Positioning systems | L119: =IF(A119,"страховочная привязь с поясным ремнем, строп регулируемой длины для позиционирования, строп с амортизатором Safety harness with waist belt, adjustable length positioning lanyard, shock absorber lanyard","-") -> -
...

Sheet + обязательно Допуск
G1: Динамическая оценка профессиональных рисков. Ежедневный допуск к работе Daily work permit | V1: Наряд № PTW №
A4: Дата Date | D4: Место проведения работ Place of work | G4: Проведена динамическая оценка профессиональных рисков A dynamic assessment of professional risks was carried out | L4: Бригада получила целевой инструктаж и допущена на подготовленное рабочее место The team received target training and was admitted to the prepared workplace | V4: Работа закончена, бригада выведена с места проведения работ. The work has been completed, the team has withdrawn from the place of work
L10: Ответственный руководитель работ Head of works | Q10: Ответственный исполнитель работ Responsible work executor | V10: Ответственный исполнитель работ Responsible work executor
G13: Время Time | I13: Подпись Signature | L13: Время Time | N13: ` | Q13: Время Time | S13: Подпись Signature | V13: Время Time | X13: Подпись Signature
A15: ='Наряд на РПО'!E8 -> 46316 | D15: ='Наряд на РПО'!H20 -> 10UJA from elev. -0.100/ +6.800 | G15: ='Наряд на РПО'!N8 -> 0.29166667 | L15: ='Наряд на РПО'!N8 -> 0.29166667 | Q15: ='Наряд на РПО'!N8 -> 0.29166667 | V15: 0.6875
G16: 0.54166667
A17: =A15+1 -> 46317 | D17: ='Наряд на РПО'!H20 -> 10UJA from elev. -0.100/ +6.800 | G17: =G15 -> 0.29166667 | L17: =$L$15 -> 0.29166667 | Q17: =Q15 -> 0.29166667 | V17: 0.6875
G18: =G16 -> 0.54166667
A19: =A17+1 -> 46318 | D19: ='Наряд на РПО'!H20 -> 10UJA from elev. -0.100/ +6.800 | G19: =G17 -> 0.29166667 | L19: =$L$15 -> 0.29166667 | Q19: =Q17 -> 0.29166667 | V19: 0.6875
G20: =G18 -> 0.54166667
A21: =A19+1 -> 46319 | D21: ='Наряд на РПО'!H20 -> 10UJA from elev. -0.100/ +6.800 | G21: =G19 -> 0.29166667 | L21: =$L$15 -> 0.29166667 | Q21: =Q19 -> 0.29166667 | V21: 0.6875
G22: =G20 -> 0.54166667
A23: =A21+1 -> 46320 | D23: ='Наряд на РПО'!H20 -> 10UJA from elev. -0.100/ +6.800 | G23: =G21 -> 0.29166667 | L23: =$L$15 -> 0.29166667 | Q23: =Q21 -> 0.29166667 | V23: 0.6875
G24: =G22 -> 0.54166667
A25: =A23+1 -> 46321 | D25: ='Наряд на РПО'!H20 -> 10UJA from elev. -0.100/ +6.800 | G25: =G23 -> 0.29166667 | L25: =$L$15 -> 0.29166667 | Q25: =Q23 -> 0.29166667 | V25: 0.6875
G26: =G24 -> 0.54166667
A27: =A25+1 -> 46322 | D27: ='Наряд на РПО'!H20 -> 10UJA from elev. -0.100/ +6.800 | G27: =G25 -> 0.29166667 | L27: =$L$15 -> 0.29166667 | Q27: =Q25 -> 0.29166667 | V27: 0.6875
G28: =G26 -> 0.54166667
A29: =A27+1 -> 46323 | D29: ='Наряд на РПО'!H20 -> 10UJA from elev. -0.100/ +6.800 | G29: =G27 -> 0.29166667 | L29: =$L$15 -> 0.29166667 | Q29: =Q27 -> 0.29166667 | V29: 0.6875
G30: =G28 -> 0.54166667
A31: =A29+1 -> 46324 | D31: ='Наряд на РПО'!H20 -> 10UJA from elev. -0.100/ +6.800 | G31: =G29 -> 0.29166667 | L31: =$L$15 -> 0.29166667 | Q31: =Q29 -> 0.29166667 | V31: 0.6875
G32: =G30 -> 0.54166667
A33: =A31+1 -> 46325 | D33: ='Наряд на РПО'!H20 -> 10UJA from elev. -0.100/ +6.800 | G33: =G31 -> 0.29166667 | L33: =$L$15 -> 0.29166667 | Q33: =Q31 -> 0.29166667 | V33: 0.6875
G34: =G32 -> 0.54166667
A35: =A33+1 -> 46326 | D35: ='Наряд на РПО'!H20 -> 10UJA from elev. -0.100/ +6.800 | G35: =G33 -> 0.29166667 | L35: =$L$15 -> 0.29166667 | Q35: =Q33 -> 0.29166667 | V35: 0.6875
G36: =G34 -> 0.54166667
A37: =A35+1 -> 46327 | D37: ='Наряд на РПО'!H20 -> 10UJA from elev. -0.100/ +6.800 | G37: =G35 -> 0.29166667 | L37: =$L$15 -> 0.29166667 | Q37: =Q35 -> 0.29166667 | V37: 0.6875
G38: =G36 -> 0.54166667
A39: =A37+1 -> 46328 | D39: ='Наряд на РПО'!H20 -> 10UJA from elev. -0.100/ +6.800 | G39: =G37 -> 0.29166667 | L39: =$L$15 -> 0.29166667 | Q39: =Q37 -> 0.29166667 | V39: 0.6875
G40: =G38 -> 0.54166667
A41: =A39+1 -> 46329 | D41: ='Наряд на РПО'!H20 -> 10UJA from elev. -0.100/ +6.800 | G41: =G39 -> 0.29166667 | L41: =$L$15 -> 0.29166667 | Q41: =Q39 -> 0.29166667 | V41: 0.6875
G42: =G40 -> 0.54166667
A43: =A41+1 -> 46330 | D43: ='Наряд на РПО'!H20 -> 10UJA from elev. -0.100/ +6.800 | G43: =G41 -> 0.29166667 | L43: =$L$15 -> 0.29166667 | Q43: =Q41 -> 0.29166667 | V43: 0.6875
G44: =G42 -> 0.54166667

Sheet + обязательно инструктаж
G1: Лист ознакомления с инструктажем перед началом работ (TBT) | T1: Наряд № PTW №
A3: Наименование организации: Contractor: | I3: ='Наряд на РПО'!G6 -> Филиал Общества с ограниченной ответственностью «Трест Росспецэнергомонтаж» Египет, г. Каир Branch office of "Trest RosSEM" LLC, Cairo, Egypt
A5: Место проведения работ: Work location: | G5: ='Наряд на РПО'!H20 -> 10UJA from elev. -0.100/ +6.800
A7: Наряд-допуск №: Work Permit №: | N7: Дата: Date: | U7: ='Наряд на РПО'!E8 -> 46316
A9: Наименование работ: Name of works: | G9: ='Наряд на РПО'!H18 -> Ремонт дефектов поверхностей ЖК, бетонной смесью или ремонтным составом/Repair of LCD surface defects with concrete mixture or repair compound
A11: Риски, связанные с проведением работ, меры безопасности, требования к СИЗ: Risks associated with work, safety measures, requirements for PPE:
A13: Риски: Risks: | D13: Ремонт дефектов поверхностей ЖК, бетоной смесью или ремонтным составом монтаж демонтаж лесов туры.Резка металла,бетона УШМ, шлифовка металла и бетона.
A15: Меры безопасности: Safety Precautions: | G15: Страховочная привязь, Лицевой щиток, Беруши/наушники, Защита от искр, Огнетушители, Аптечка первой медицинской помощи, Проверка лесов,туры. Проверка лестницы, Достаточное освещение, Знаки безопасности, Ограждение, Безопасный доступ/вход, Аварийный доступ/выход, Проверка рабочего места, Наблюдающий. Связь.Safety Harness, Face shield, Ear Plugs / Muffs, Spark protection, Fire extinguishers, First aid kit, Scaffold Checked, Stairs checked, Adequate Lighting, Caution Boards Displayed, Guardrails, Safe Access/Ingress, Emergency Access/Egress, Workplace checked, Supervision. Communications.
A17: Требования к СИЗ: Rrequirements for PPE: | G17: Целостность, годность к использованию согласно паспорта
A19: Тема собрания (заранее определена или с учетом условий, применяемого оборудования): Topic of the meeting (pre-determined or taking into account the conditions and equipment used):
A21: Целевой инструктаж перед началом работ с учетом условий выполняемых работ и применяемого оборудования Targeted briefing before starting work, taking into account the conditions of the work being performed and the equipment used
A23: Подписи работников Signatures of workers
A25: (Внимание: Ваша подпись означает, что Вы ознакомлены с соответствующими рисками, связанными с проведением работ, мерами безопасности и требованиями к СИЗ, подтверждаете их соблюдение) (Attention: Your signature means that you are familiar with the relevant risks associated with the work, safety measures and PPE requirements, and confirm their compliance)
A28: № п/п | B28: Наименование организации: Contractor: | E28: Ф.И.О. Full name | L28: Подпись Signature | N28: № п/п | O28: Наименование организации: Contractor: | R28: Ф.И.О. Full name | Y28: Подпись Signature
A30: 1 | B30: Trest RosSEM | N30: 19 | O30: Trest RosSEM
A31: 2 | B31: Trest RosSEM | N31: 20 | O31: Trest RosSEM
A32: 3 | B32: Trest RosSEM | N32: 21 | O32: Trest RosSEM
A33: 4 | B33: Trest RosSEM | N33: 22 | O33: Trest RosSEM
A34: 5 | B34: Trest RosSEM | N34: 23 | O34: Trest RosSEM
A35: 6 | B35: Trest RosSEM | N35: 24 | O35: Trest RosSEM
A36: 7 | B36: Trest RosSEM | N36: 25 | O36: Trest RosSEM
A37: 8 | B37: Trest RosSEM | N37: 26 | O37: Trest RosSEM
A38: 9 | B38: Trest RosSEM | N38: 27 | O38: Trest RosSEM
A39: 10 | B39: Trest RosSEM | N39: 28 | O39: Trest RosSEM
A40: 11 | B40: Trest RosSEM | N40: 29 | O40: Trest RosSEM
A41: 12 | B41: Trest RosSEM | N41: 30 | O41: Trest RosSEM
... A47: 18 | B47: Trest RosSEM | N47: 36 | O47: Trest RosSEM
A48: Организатор собрания: Meeting organizer: | G48: ='Наряд на РПО'!V12 -> Foreman | M48: ='Наряд на РПО'!I12 -> Pavlov V.E.
G50: (должность/position) | M50: (Ф.И.О./full name) | U50: (подпись/personal signature)
G51: Лист ознакомления с инструктажем перед началом работ (TBT) | T51: Наряд № PTW №
A53: Наименование организации: Contractor: | I53: ='Наряд на РПО'!G56 -> Опасные химические вещества и жидкости Dangerous chemicals and liqids
A55: Место проведения работ: Work location: | G55: ='Наряд на РПО'!H20 -> 10UJA from elev. -0.100/ +6.800
A57: Наряд-допуск №: Work Permit №: | N57: Дата: Date: | U57: ='Наряд на РПО'!E8 -> 46316
A59: Наименование работ: Name of works: | G59: ='Наряд на РПО'!H18 -> Ремонт дефектов поверхностей ЖК, бетонной смесью или ремонтным составом/Repair of LCD surface defects with concrete mixture or repair compound
A61: Риски, связанные с проведением работ, меры безопасности, требования к СИЗ: Risks associated with work, safety measures, requirements for PPE:
A63: Риски: Risks: | D63: Ремонт дефектов поверхностей ЖК, бетоной смесью или ремонтным составом монтаж демонтаж лесов туры.Резка металла,бетона УШМ, шлифовка металла и бетона.
A65: Меры безопасности: Safety Precautions: | G65: Страховочная привязь, Лицевой щиток, Беруши/наушники, Защита от искр, Огнетушители, Аптечка первой медицинской помощи, Проверка лесов,туры. Проверка лестницы, Достаточное освещение, Знаки безопасности, Ограждение, Безопасный доступ/вход, Аварийный доступ/выход, Проверка рабочего места, Наблюдающий. Связь.Safety Harness, Face shield, Ear Plugs / Muffs, Spark protection, Fire extinguishers, First aid kit, Scaffold Checked, Stairs checked, Adequate Lighting, Caution Boards Displayed, Guardrails, Safe Access/Ingress, Emergency Access/Egress, Workplace checked, Supervision. Communications.
A67: Требования к СИЗ: Rrequirements for PPE: | G67: Целостность, годность к использованию согласно паспорта
A69: Тема собрания (заранее определена или с учетом условий, применяемого оборудования): Topic of the meeting (pre-determined or taking into account the conditions and equipment used):
A71: Целевой инструктаж перед началом работ с учетом условий выполняемых работ и применяемого оборудования Targeted briefing before starting work, taking into account the conditions of the work being performed and the equipment used
...

Sheet ППРВ
O1: УТВЕРЖДАЮ APPROVED BY
O3: ='Наряд на РПО'!D213 -> Temporary the head of the site
O5: (должность/posoition)
T6: ='Наряд на РПО'!K213 -> Alferov A.V.
O8: (подпись/signature) | T8: (Ф.И.О./full name)
U9: ='Наряд на РПО'!E8 -> 46316
U11: (дата/date)
A12: ПЛАН ПРОИЗВОДСТВА РАБОТ НА ВЫСОТЕ WORK AT HEIGHTS METHOD STATEMENT
I15: к наряду(ам) - допуску(ам) № to permit(s)-to-work № | R15: -
A17: (Основание: п. 36 «Правил по охране труда при работе на высоте, утв. Минтруда РФ от16.11.2020 N 782н») (Grounds: clause. 36 of “Job safety rules by work at heights, approved by Minister of Labor of the RF No.782n” dated 16.11.2020)
A19: 1. | B19: Выполняемые работы: Works performed: | H19: ='Наряд на РПО'!H18 -> Ремонт дефектов поверхностей ЖК, бетонной смесью или ремонтным составом/Repair of LCD surface defects with concrete mixture or repair compound
A21: 2. | B21: Место выполнения работ: Work site: | I21: ='Наряд на РПО'!H20 -> 10UJA from elev. -0.100/ +6.800
A23: 3. | B23: Группы по безопасности при работах на высоте: Work at heights safety groups:
A25: Ответственный руководитель работ Responsible head of works | J25: Ответственный исполнитель (производитель) работ Responsible work executor (producer) | U25: Член бригады Member of the team
A27: 3 группа | J27: 2 группа | U27: 1 или 2 группа
A29: Наличие у работника удостоверения о допуске к работам на высоте на рабочем месте обязательно!
A33: 4. | B33: Системы обеспечения безопасности работ на высоте: Work at heights safety systems:
A35: Наименование системы System denomination (отметить исходя из конкретных условий) (to be marked basing on particular circumstances) | H35: Состав (элементы) системы System composition (elements) (отметить выбор исходя из конкретных условий работ, при необходимости внести дополнительные элементы) (to be marked basing on particular circumstances of works, additional elements to be entered if necessary) | W35: Потребность (кол-во, шт.) Replenishment (quantity, pcs.)
B40: Удерживающие системы Restraint systems | I40: Страховочная привязь (огнестойкая) Safety harness (fire-resistant)
I42: Строп удерживающий, регулируемый (огнестойкий), с соединительными элементами (карабинами) Adjustable lanyard (fire-resistant) with fasteners (snap hooks)
I45: Анкерная точка крепления или анкерная линия Anchor point or anchor line
I47: Анкерное устройство или структурный анкер Anchoring system or structural anchor
I49: Дополнительно: Additionally:
B51: Системы позиционирования Positioning systems | I51: Страховочная привязь (огнестойкая) Safety harness (fire-resistant)
I53: На любой высоте - инерционное блокирующее устройство втягивающего типа At any height - self-retracting lanyard
I56: На высоте до 6,0 метров - двуплечевое блокирующее устройство втягивающего типа At heights below 6.0 meters - two-arm self-retracting lifeline
I59: На высоте от 6,0 метров - строп страховочный двуплечевой, регулируемый (огнестойкий), с амортизатором и соединительными элементами (карабинами) At heights over 6.0 meters - two-arm adjustable lanyard (fire-resistant) with shock-absorber and fasteners (snap hooks)
I63: Строп для позиционирования регулируемый (огнестойкий) Adjustable lanyard (fire-resistant) for positioning
I65: Дополнительно: Additionally:
B67: Страховочные системы Fall arrest systems | I67: Страховочная привязь (огнестойкая) Safety harness (fire-resistant)
I69: На любой высоте - инерционное блокирующее устройство втягивающего типа с соединительными элементами (карабинами) At any height - self-retracting lanyard with fasteners (snap hooks)
I72: На высоте до 6,0 метров - двуплечевое блокирующее устройство втягивающего типа с соединительными элементами (карабинами) At heights below 6.0 meters - two-arm self-retracting lifeline with fasteners (snap hooks)
I76: На высоте от 6,0 метров - строп страховочный двуплечевой, регулируемый (огнестойкий), с амортизатором и соединительными элементами (карабинами) At heights over 6.0 meters - two-arm adjustable lanyard (fire-resistant) with shock-absorber and fasteners (snap hooks)
I81: Анкерная точка крепления или анкерная линия Anchor point or anchor line
I83: Анкерное устройство (петля) или структурный анкер Anchoring system (loop) or structural anchor
I85: Дополнительно: Additionally:
B87: Эвакуационные и спасательные системы Evacuation and rescue systems | I87: Страховочная привязь (огнестойкая) Safety harness (fire-resistant) | W87: 1
I89: Анкерная точка крепления или анкерная линия Anchor point or anchor line
I91: Средство защиты втягивающего типа со встроенным спасательным подъемным устройством Self-retracting safety device with built-in rescue lifting gear | W91: 1
A95: 5. | B95: Первоочередное устройство постоянных ограждающих конструкций: Primary arrangement of permanent safety barriers: | N95: Под местом производства работ на высоте в обязательном порядке устанавливать защитные улавливающие сетки, защитные экраны, козырьки и другие ограждающие конструкции предотвращающие падение предметов с высоты на ниже расположенные места производства работ и отметки. It is mandatory to install safety nets, protective screens, canopies and other protective structures at the site of work at height to prevent objects from falling from a height onto work areas and levels situated below.
...

Sheet ПСЭР
O1: УТВЕРЖДАЮ APPROVED BY
O4: ='Наряд на РПО'!D213 -> Temporary the head of the site
O6: (должность/posoition)
T7: ='Наряд на РПО'!K213 -> Alferov A.V.
O9: (подпись/signature) | T9: (Ф.И.О./full name)
U10: ='Наряд на РПО'!E8 -> 46316
U12: (дата/date)
A13: ПЛАН ПО СПАСЕНИЮ И ЭВАКУАЦИИ РАБОТНИКОВ ПРИ ПРОИЗВОДСТВЕ РАБОТ НА ВЫСОТЕ A PLAN FOR THE RESCUE AND EVACUATION OF WORKERS DURING WORK AT A HEIGHT
I19: к наряду - допуску № to permit-to-work № | R19: -
A21: (Основание: п. 35 «Правил по охране труда при работе на высоте, утв. Минтруда РФ от16.11.2020 N 782н») (Grounds: clause. 35 of “Job safety rules by work at heights, approved by Minister of Labor of the RF No.782n” dated 16.11.2020)
A23: 1. | B23: Выполняемые работы: Works performed: | H23: ='Наряд на РПО'!H18 -> Ремонт дефектов поверхностей ЖК, бетонной смесью или ремонтным составом/Repair of LCD surface defects with concrete mixture or repair compound
A25: 2. | B25: Место выполнения работ: Work site: | I25: ='Наряд на РПО'!H20 -> 10UJA from elev. -0.100/ +6.800
A27: 3. | B27: Группы по безопасности при работах на высоте: Work at heights safety groups:
A29: Ответственный руководитель работ Responsible head of works | J29: Ответственный исполнитель (производитель) работ Responsible work executor (producer) | U29: Член бригады Member of the team
A31: 3 группа | J31: 2 группа | U31: 1 или 2 группа
A34: Опыт непосредственного выполнения работ на высоте: Experience of direct performance of work at height: | N34: Не менее одного года
A36: Требования к ключевым навыкам: Key skill requirements: | N36: 1. Навык проведения спасательных мероприятий The skill of conducting rescue operations 2. Навык организации безопасной транспортировки пострадавшего The skill of organizing the safe transportation of the victim 3. Навык оказания первой помощи пострадавшему The skill of providing first aid to the victim
A43: Наличие у работника удостоверения о допуске к работам на высоте на рабочем месте обязательно!
A46: Требования к оформлению наряда-допуска на проведение спасательных работ
A47: Согласно пункту 49 Приказа Минтруда России № 782н от 16.11.2020 в исключительных случаях(предупреждение аварии, устранение угрозы жизни работников, ликвидацияпоследствий аварий и стихийных бедствий) работы на высоте могут начаты без оформления наряда-допуска под руководством работников, назначаемых работодателем ответственными за безопасную организацию и проведение работ на высоте. Если указанные работы выполняются более суток, оформление наряда-допуска должно быть произведено в обязательном порядке. При этом распределение обязанностей в наряде допуске производится согласно представленной ниже таблице: According to paragraph 49 of the Order of the Ministry of Labor of the Russian Federation No. 782n dated 11.16.2020, in exceptional cases (accident prevention, elimination of threats to workers' lives, elimination of the consequences of accidents and natural disasters), work at height can begin without registration of a work permit under the supervision of employees appointed by the employer responsible for the safe organization and conduct of work at height. If the specified work is performed for more than a day, registration of the work permit must be carried out without fail. In this case, the distribution of responsibilities in the admission outfit is carried out according to the table below.:
A65: Функции по наряду-допуску Access control functions | J65: Назначаемое должностное лицо Appointed official | U65: Требования к группе безопасности работ на высоте Requirements for the work safety group at height
A67: Ответственный руководитель работ по наряду-допуску Responsible supervisor of the work on the side-admission | J67: Лицо, назначенное приказом организации, ответственным за безопасную организацию и проведение работ на высоте. The person appointed by the order of the organization responsible for the safe organization and performance of work at height. | U67: 3 группа Group 3
A71: Ответственный исполнитель работ по наряду допуску Responsible contractor for joint admission | J71: Лицо, уполномоченное приказом организации на проведение спасательных мероприятий и исполнению функций ответственного исполнителя работ. The person authorized by the order of the organization to carry out rescue operations and perform the functions of the responsible contractor. | U71: 2 группа Group 2
A75: Члены бригады Members of the brigade | J75: Лица, уполномоченные приказом организации на проведение спасательных мероприятий. Persons authorized by the organization's order to carry out rescue operations. | U75: 2 и 1 группа Groups 2 and 1
A79: Способ коммуникации ответственного исполнителя работ с ответственным руководителем работ и экстренными службами: Телефонная связь The method of communication of the duty officer (supervisor) with the responsible head of work and emergency services: Telephone connection
A87: Ответственный руководитель работ Responsible head of works | H87: номер телефона: phone number:
A90: Медицинская служба: +201070902111 (дежурный, круглосуточно) | H90: Medical service:+201070902111 (duty officer, around the clock)
A94: Ответственный исполнитель сообщает ответственному руководителю работ и экстренным службам следующую информацию: The responsible contractor informs the responsible work manager and the emergency services of the following information:
A100: ФИО, сообщившего о проишествии Full name of the person who reported the incident
A104: Место проишествия (название объекта, отметка, градус, оси) Location of the incident (name of the object, mark, degree, axis)
A108: Характер проишествия The nature of the incident
A110: Количество пострадавших Number of victims
A112: Признаки травм у пострадавшего Signs of injury in the victim
A115: Особенности путей подхода к пострадшему Features of the ways of approach to the victim
A119: Местонахождение пострадавшего Location of the victim
A121: Номер контактного (мобильного телефона) Contact (mobile phone) number
A124: Если нет прямой связи с ответственным руководителем работ и экстенными службами, передать через третье лицо необходимую информацию If there is no direct communication with the responsible work manager and emergency services, provide the necessary information through a third party.
A129: Номер телефона Phone number
A131: Контактное лицо Contact person
... A144: Анкерные устройства и/или анкерные линии (дополнительные или уже используемые, но расчитанные на дополнительную нагрузку): Anchoring devices and/or anchor lines (additional or already used, but designed for additional load):
...

Sheet Приложение № 1
A1: Приложение № 1 к Плану мероприятий при аварийной ситуации и при проведении спасательных работ при работах на высоте
A9: Порядок необходимых действий по оказанию первой помощи пострадавшим
A16: 1. Действия по оценке обстановки и обеспечению безопасных условий для оказания первой помощи пострадавшим при несчастных случаях: - определить угрожающие факторы для собственной жизни и здоровья; - определить угрожающие факторы для жизни и здоровья пострадавшего; - устранить угрожающие факторы для жизни и здоровья; - прекратить действие травмирующих факторов на пострадавшего; - определить число пострадавших; - вытащить потрадавшего из труднодоступных мест; -переместить пострадавшего в безопасное место. 1. Actions to assess the situation and ensure safe conditions for first aid to victims of accidents: - identify threatening factors for your own life and health; - identify threatening factors for the life and health of the victim; - eliminate life- and health-threatening factors; - stop the effect of traumatic factors on the victim; - determine the number of victims; - get the victim out of hard-to-reach places; -move the victim to a safe place. 2. Вызвать скорую помощь 2. Call an ambulance 3. Определить наличие сознания у пострадавшего. 3. Determine the presence of consciousness in the victim. 4. Действия по восстановлению дыхательных путей и выявлению признаков жизни у пострадавшего: - запрокинуть голову с подъемом подбородка; - выдвинуть нижнюю челюсть; - установить присутствие дыхания при помощи слуха, зрения и осязания; - определить наличие кровообращения, проверить пульс на магистральных артериях. 4. Actions to restore the respiratory tract and identify signs of life in the victim: - tilt your head back with a lift of the chin; - extend the lower jaw; - establish the presence of breathing using hearing, sight and touch; - determine the presence of blood circulation, check the pulse on the main arteries; 5. Действия по выполнению сердечно-легочной реанимации до появления признаков жизни: - давление руками на нгрудину пострадавшего; - искуственное дыхание "рот в рот"; - искуственное дыхание "рот к носу"; - искуственное дыхание с применением устройства для искуственного дыхания. 5. Actions to perform cardiopulmonary resuscitation before the appearance of signs of life: - hand pressure on the victim's chest; - mouth-to-mouth artificial respiration; - mouth-to-nose artificial respiration; - artificial respiration using an artificial respiration device. 6. Действия по поддержаниюпроходимости дыхательных путей: - придать устойчивое боковое положение; - запрокинуть голову, подняв подбородок; -выдвинуть нижнюю челюсть. 6. Actions to maintain airway permeability: - to give a stable lateral position; - tilt your head back, lifting your chin; - extend the lower jaw. 7. Действия по общему осмотру пострадавшего и временной остановке внешненго кровотечения: - провести общий осмотр пострадавшего на присутствие кровотечений; - провести пальцевое прижатие артерии; - наложить жгут; - максимально согнуть конечность в суставе; - прямо надовить на рану; - наложить давящую повязку. 7. Actions for general examination of the victim and temporary stopping of external bleeding: - conduct a general examination of the victim for the presence of bleeding; - perform finger compression of the artery; - apply a tourniquet; - bend the limb at the joint as much as possible; - directly put pressure on the wound; - apply a pressure bandage. 8. Действия поподробному осмотру пострадавшего с целью выявления признаков травм, отравлений и иных состояний, представляющих угрозу жизни и здоровью и по оказанию первой медицинской помощи при выявлении прерчисленных состояний: - осмотреть голову; - осмотреть шею и грудь; - осмотреть спину живот и таз; -осмотреть конечности; - наложить повязки при травмах различных областей тела, в том числе герметизирующей, при ранении грудной клетки; - проведение имобилизации ( с помощью подручных средств, аутоимобилизация, с использованием изделий медицинского назначения); - фиксация шейного отдела позвоночника (вручную, подручными средствами, с использованием изделий медицинского назначения); - прекращение воздействия опасных химических веществ на пострадавшего (промывание желудка путем приема воды и вызывания рвоты, удаление с поврежденной поверхности проточной водой); - местное охлаждение при травмах, термических ожогах и иных воздействиях высоких температур или теплового излучения; - термоизоляция при отморожениях и других эффектах воздействия температур. 8. Actions for a detailed examination of the victim in order to identify signs of injuries, poisoning and other conditions that pose a threat to life and health, and to provide first aid when identifying the listed conditions.: - examine the head; - examine the neck and chest; - examine your back, stomach and pelvis; - examine the limbs; - apply bandages for injuries to various areas of the body, including the sealing area, for chest wounds; - carrying out immobilization (using improvised means, auto-immobilization, using medical devices); - fixation of the cervical spine (manually, by improvised means, using medical devices); - cessation of exposure to dangerous chemicals on the victim (gastric lavage by ingestion of water and vomiting, removal from the damaged surface with running water); - local cooling in case of injuries, thermal burns and other effects of high temperatures or thermal radiation; - thermal insulation in case of frostbite and other effects of exposure to temperatures. 9. Придать пострадавшему оптимального положения тела. 9. Give the victim an optimal body position. 10. Контроль состояния пострадавшего (сознание, дыхание, кровообращение) и оказание психологической поддержки. 10. Monitoring the condition of the victim (consciousness, breathing, blood circulation) and providing psychological support. 11. Передача пострадавшего бригаде скорой медицинской помощи. 11. Transfer of the victim to the ambulance team.

Sheet ЛО ПСЭР
G1: Лист ознакомления работников с Планом спасения и эвакуации при производстве работ на высоте | U1: Наряд № PTW № | Y1: -
A6: Наименование организации: Contractor: | I6: ='[1]Наряд на РПО'!G6 -> Филиал Общества с ограниченной ответственностью «Трест Росспецэнергомонтаж» Египет, г. Каир Branch office of "Trest RosSEM" LLC, Cairo, Egypt
A10: Подписи работников Signatures of workers
A13: № п/п | B13: Наименование организации: Contractor: | F13: Ф.И.О. Full name | L13: Подпись Signature | O13: № п/п | P13: Наименование организации: Contractor: | T13: Ф.И.О. Full name | Z13: Подпись Signature
A18: 1 | B18: Trest RosSEM | O18: 19 | P18: Trest RosSEM
A19: 2 | B19: Trest RosSEM | O19: 20 | P19: Trest RosSEM
A20: 3 | B20: Trest RosSEM | O20: 21 | P20: Trest RosSEM
A21: 4 | B21: Trest RosSEM | O21: 22 | P21: Trest RosSEM
A22: 5 | B22: Trest RosSEM | O22: 23 | P22: Trest RosSEM
A23: 6 | B23: Trest RosSEM | O23: 24 | P23: Trest RosSEM
A24: 7 | B24: Trest RosSEM | O24: 25 | P24: Trest RosSEM
A25: 8 | B25: Trest RosSEM | O25: 26 | P25: Trest RosSEM
A26: 9 | B26: Trest RosSEM | O26: 27 | P26: Trest RosSEM
A27: 10 | B27: Trest RosSEM | O27: 28 | P27: Trest RosSEM
A28: 11 | B28: Trest RosSEM | O28: 29 | P28: Trest RosSEM
A29: 12 | B29: Trest RosSEM | O29: 30 | P29: Trest RosSEM
... A35: 18 | B35: Trest RosSEM | O35: 36 | P35: Trest RosSEM
A36: Организатор собрания: Meeting organizer: | F36: ='Наряд на РПО'!V12 -> Foreman | L36: ='Наряд на РПО'!I12 -> Pavlov V.E.
F42: __________________ (должность/position) | L42: __________________ (Ф.И.О./full name) | T42: __________________ (Подпись/ Signature)

Sheet Огневой
E1: Проект АЭС «Эль-Дабаа» | H1: Наряд-допуск на проведение огневых работ Permit to work for hot works
A4: Наряд-допуск №: Permit to work №: | I4: Дата выдачи: Issue date: | M4: ='Наряд на РПО'!E8 -> 46316 | Q4: К наряд-допуску №: To the permit to work №:
A6: Дата и время начала работ: Date and time of the start of work: | I6: ='Наряд на РПО'!E8 -> 46316 | L6: ='Наряд на РПО'!N8 -> 0.29166667 | N6: Дата и время окончания работ: Date and time of completion of the work: | W6: ='Наряд на РПО'!E8 -> 46316 | Y6: ='Наряд на РПО'!N10 -> 0.70833333
A8: Наряд допуск выдал: Permit to work issued by: | G8: ='Наряд на РПО'!K213 -> Alferov A.V. | M8: _____________ (подпись / signature) | P8: Должность: Position: | T8: ='Наряд на РПО'!D213 -> Temporary the head of the site
A10: Описание работ: Description of the work: | G10: Резка металла,бетона УШМ, шлифовка металла и бетона.Cutting of metal, grinding metal, welding works and concrete.
A12: Место проведения работ: Place of work: | G12: ='Наряд на РПО'!H20 -> 10UJA from elev. -0.100/ +6.800
A14: Лицо ответственное за подготовку огневых работ (Ф.И.О.): The person responsible for preparation of hot works (full name): | O14: ='Наряд на РПО'!I12 -> Pavlov V.E. | R14: __________ ( signature) | T14: Должность: Position: | W14: ='Наряд на РПО'!V12 -> Foreman
A16: Лицо ответственное за проведение огневых работ (Ф.И.О.): The person responsible for carrying out hot works (full name): | R16: __________ ( signature) | T16: Должность: Position:
A18: Наряд-допуск зарегистрирован: The prmit order is registered by: | I18: Специалист по ОТ (Ф.И.О., подпись) HSE (Full name, signature) | V18: Дата: Date: | X18: ='Наряд на РПО'!E8 -> 46316
A20: Согласовано со структурными подразделениями объекта, на котором будут производиться огневые работы: Agreed with the structural departments of the facility where the hot work will be carried out:
A22: Наименование структурного подразделения: Name of the structural unit: | K22: MU-12
A24: Руководитель подразделения (Ф.И.О.): Head of the unit (full name): | O24: Подпись: Signature: | V24: Дата: Date: | X24: ='Наряд на РПО'!E8 -> 46316
A26: 1. | B26: Исполнители огневых работ: Performers of hot work:
A28: № п/п Item no. | B28: Состав бригады исполнителей огневых работ, инициалы и фамилия The composition of the work team performers of hot works, initials and surname | J28: Профессия рабочего The profession of the worker | Q28: Целевой противопожарный инструктаж Targeted fire prevention briefing
Q30: Провел Conducted | V30: Получил Passed
Q32: (подпись лица, проводившего инструктаж) (signature of the person conducting the briefing) | V32: (подписи исполнителей огневых работ) (signatures of performers hot work)
A36: 1
A38: 2
A40: 3
A42: 4
A44: 5
A46: 6
A48: 7
A50: 8
A52: 9
A54: 10
A56: 11
A58: 12
... A104: 35
A106: 2. | B106: До начала производства работ необходимо выполнить следующие отмеченные мероприятия Before the start of work, the following noted activities shall be performed
A108: Отметка Mark | C108: Мероприятия Activities | G108: Отметка Mark | I108: Мероприятия Activities | O108: Отметка Mark | Q108: Мероприятия Activities | U108: Отметка Mark | W108: Мероприятия Activities
C110: Проведение целевого инструктажа Conducting targeted briefing | I110: Установка вентиляции в помещении Installation of ventilation in the room | Q110: Закрепление и защита баллонов Securing and protecting cylinders | W110: Анализ воздушной среды Analysis of the air environment
C115: Наличие средств пожаротушения (2 огнетушителя и противопожарное полотно) Availability of fire extinguishers equipment (2 fire extinguishers and a fire protection cloth) | I115: Конструкции строительных лесов/подмостей выполнены из негорючих материалов/выполнена пропитка огнезащитным составом Scaffolding structures/the scaffolding is made of non-flammable materials/impregnated with a flame retardant | Q115: Наличие исправных манометров на газовых баллонах Availability of serviceable pressure gauges on gas cylinders | W115: Исключено падение раскаленных частиц металла на нижние отметки здания Dropping of incandescent metal particles on the building is excluded
C124: Очистка зоны мест проведения огневых работ от горючих материалов Cleaning of the aria of hot works from combustible materials | I124: Установка защитных щитов (экранов) от разлета раскаленных частиц металла/в местах массового прохода работников Installation of protective shields (screens) from the spread of incandescent metal particles/in places of mass passage of workers | Q124: Инспекция шлангов и их защита Hose inspection and protection | W124: Ограждение зоны мест проведения огневых работ Fencing the zone of hot work sites
C132: Отсутствие совмещеных работ по производству окрасочных работ The absence of combined works on the execution of painting works | I132: Строп СИЗ от падения с высоты выполнен из несгораемых материалов The sling of the PPE from falling from a height is made of fireproof materials | Q132: Заземление оборудования Grounding of equipment | W132: Другое (При необходимости дописать) Other (add if necessary)
A139: 3. | B139: Мероприятия по безопасности при проведении работ Safety measures during the work
A141: № п/п | B141: Мероприятия Activities
A143: 1 | B143: Осмотреть и подготовить рабочее место, убрать все лишние предметы, не загромождая при этом проходов и обеспечить отсутствие легковоспламеняющихся и горючих материалов в радиусе, указанном в таблице: Inspection and prepare the workplace, remove all extra objects without blocking the passages and ensure the absence of flammable and combustible materials in the radius indicated in the table:
C147: Высота точки сварки (резки) над уровнем пола (земли), м The height of the welding (cutting) point above the floor (ground) level, m | O147: Минимальное расстояние разлёта искр, м Minimum distance of sparks, m
O149: при сварке when welding | T149: при резке when cutting
...
